[2025-05-30T05:23:56.787+0000] {local_task_job_runner.py:123} INFO - ::group::Pre task execution logs
[2025-05-30T05:23:56.802+0000] {taskinstance.py:2603} INFO - Dependencies all met for dep_context=non-requeueable deps ti=<TaskInstance: read_csv_sum_dag.read_and_sum_csv manual__2025-05-30T05:23:55.312679+00:00 [queued]>
[2025-05-30T05:23:56.809+0000] {taskinstance.py:2603} INFO - Dependencies all met for dep_context=requeueable deps ti=<TaskInstance: read_csv_sum_dag.read_and_sum_csv manual__2025-05-30T05:23:55.312679+00:00 [queued]>
[2025-05-30T05:23:56.809+0000] {taskinstance.py:2856} INFO - Starting attempt 1 of 1
[2025-05-30T05:23:56.822+0000] {taskinstance.py:2879} INFO - Executing <Task(PythonOperator): read_and_sum_csv> on 2025-05-30 05:23:55.312679+00:00
[2025-05-30T05:23:56.827+0000] {standard_task_runner.py:72} INFO - Started process 401 to run task
[2025-05-30T05:23:56.862+0000] {standard_task_runner.py:104} INFO - Running: ['***', 'tasks', 'run', 'read_csv_sum_dag', 'read_and_sum_csv', 'manual__2025-05-30T05:23:55.312679+00:00', '--job-id', '20', '--raw', '--subdir', 'DAGS_FOLDER/read_csv_sum_dag.py', '--cfg-path', '/tmp/tmpm_cr25ht']
[2025-05-30T05:23:56.877+0000] {standard_task_runner.py:105} INFO - Job 20: Subtask read_and_sum_csv
[2025-05-30T05:23:56.969+0000] {logging_mixin.py:190} WARNING - /home/***/.local/lib/python3.10/site-packages/***/settings.py:209 DeprecationWarning: The sql_alchemy_conn option in [core] has been moved to the sql_alchemy_conn option in [database] - the old setting has been used, but please update your config.
[2025-05-30T05:23:57.190+0000] {task_command.py:467} INFO - Running <TaskInstance: read_csv_sum_dag.read_and_sum_csv manual__2025-05-30T05:23:55.312679+00:00 [running]> on host 1232a4f48263
[2025-05-30T05:23:57.408+0000] {taskinstance.py:3122} INFO - Exporting env vars: AIRFLOW_CTX_DAG_OWNER='***' AIRFLOW_CTX_DAG_ID='read_csv_sum_dag' AIRFLOW_CTX_TASK_ID='read_and_sum_csv' AIRFLOW_CTX_EXECUTION_DATE='2025-05-30T05:23:55.312679+00:00' AIRFLOW_CTX_TRY_NUMBER='1' AIRFLOW_CTX_DAG_RUN_ID='manual__2025-05-30T05:23:55.312679+00:00'
[2025-05-30T05:23:57.410+0000] {taskinstance.py:731} INFO - ::endgroup::
[2025-05-30T05:23:57.477+0000] {taskinstance.py:3301} ERROR - Task failed with exception
Traceback (most recent call last):
  File "/home/airflow/.local/lib/python3.10/site-packages/pandas/core/indexes/base.py", line 3791, in get_loc
    return self._engine.get_loc(casted_key)
  File "index.pyx", line 152, in pandas._libs.index.IndexEngine.get_loc
  File "index.pyx", line 181, in pandas._libs.index.IndexEngine.get_loc
  File "pandas/_libs/hashtable_class_helper.pxi", line 7080, in pandas._libs.hashtable.PyObjectHashTable.get_item
  File "pandas/_libs/hashtable_class_helper.pxi", line 7088, in pandas._libs.hashtable.PyObjectHashTable.get_item
KeyError: 'value'

The above exception was the direct cause of the following exception:

Traceback (most recent call last):
  File "/home/airflow/.local/lib/python3.10/site-packages/airflow/models/taskinstance.py", line 767, in _execute_task
    result = _execute_callable(context=context, **execute_callable_kwargs)
  File "/home/airflow/.local/lib/python3.10/site-packages/airflow/models/taskinstance.py", line 733, in _execute_callable
    return ExecutionCallableRunner(
  File "/home/airflow/.local/lib/python3.10/site-packages/airflow/utils/operator_helpers.py", line 252, in run
    return self.func(*args, **kwargs)
  File "/home/airflow/.local/lib/python3.10/site-packages/airflow/models/baseoperator.py", line 406, in wrapper
    return func(self, *args, **kwargs)
  File "/home/airflow/.local/lib/python3.10/site-packages/airflow/operators/python.py", line 238, in execute
    return_value = self.execute_callable()
  File "/home/airflow/.local/lib/python3.10/site-packages/airflow/operators/python.py", line 256, in execute_callable
    return runner.run(*self.op_args, **self.op_kwargs)
  File "/home/airflow/.local/lib/python3.10/site-packages/airflow/utils/operator_helpers.py", line 252, in run
    return self.func(*args, **kwargs)
  File "/opt/airflow/dags/read_csv_sum_dag.py", line 10, in read_and_sum
    total = df['value'].sum()  # Replace 'value' with your actual column name
  File "/home/airflow/.local/lib/python3.10/site-packages/pandas/core/frame.py", line 3893, in __getitem__
    indexer = self.columns.get_loc(key)
  File "/home/airflow/.local/lib/python3.10/site-packages/pandas/core/indexes/base.py", line 3798, in get_loc
    raise KeyError(key) from err
KeyError: 'value'
[2025-05-30T05:23:57.573+0000] {taskinstance.py:1225} INFO - Marking task as FAILED. dag_id=read_csv_sum_dag, task_id=read_and_sum_csv, run_id=manual__2025-05-30T05:23:55.312679+00:00, execution_date=20250530T052355, start_date=20250530T052356, end_date=20250530T052357
[2025-05-30T05:23:57.607+0000] {taskinstance.py:340} INFO - ::group::Post task execution logs
[2025-05-30T05:23:57.608+0000] {standard_task_runner.py:124} ERROR - Failed to execute job 20 for task read_and_sum_csv ('value'; 401)
Traceback (most recent call last):
  File "/home/airflow/.local/lib/python3.10/site-packages/pandas/core/indexes/base.py", line 3791, in get_loc
    return self._engine.get_loc(casted_key)
  File "index.pyx", line 152, in pandas._libs.index.IndexEngine.get_loc
  File "index.pyx", line 181, in pandas._libs.index.IndexEngine.get_loc
  File "pandas/_libs/hashtable_class_helper.pxi", line 7080, in pandas._libs.hashtable.PyObjectHashTable.get_item
  File "pandas/_libs/hashtable_class_helper.pxi", line 7088, in pandas._libs.hashtable.PyObjectHashTable.get_item
KeyError: 'value'

The above exception was the direct cause of the following exception:

Traceback (most recent call last):
  File "/home/airflow/.local/lib/python3.10/site-packages/airflow/task/task_runner/standard_task_runner.py", line 117, in _start_by_fork
    ret = args.func(args, dag=self.dag)
  File "/home/airflow/.local/lib/python3.10/site-packages/airflow/cli/cli_config.py", line 49, in command
    return func(*args, **kwargs)
  File "/home/airflow/.local/lib/python3.10/site-packages/airflow/utils/cli.py", line 115, in wrapper
    return f(*args, **kwargs)
  File "/home/airflow/.local/lib/python3.10/site-packages/airflow/cli/commands/task_command.py", line 483, in task_run
    task_return_code = _run_task_by_selected_method(args, _dag, ti)
  File "/home/airflow/.local/lib/python3.10/site-packages/airflow/cli/commands/task_command.py", line 256, in _run_task_by_selected_method
    return _run_raw_task(args, ti)
  File "/home/airflow/.local/lib/python3.10/site-packages/airflow/cli/commands/task_command.py", line 341, in _run_raw_task
    return ti._run_raw_task(
  File "/home/airflow/.local/lib/python3.10/site-packages/airflow/utils/session.py", line 97, in wrapper
    return func(*args, session=session, **kwargs)
  File "/home/airflow/.local/lib/python3.10/site-packages/airflow/models/taskinstance.py", line 2995, in _run_raw_task
    return _run_raw_task(
  File "/home/airflow/.local/lib/python3.10/site-packages/airflow/models/taskinstance.py", line 273, in _run_raw_task
    TaskInstance._execute_task_with_callbacks(
  File "/home/airflow/.local/lib/python3.10/site-packages/airflow/models/taskinstance.py", line 3149, in _execute_task_with_callbacks
    result = self._execute_task(context, task_orig)
  File "/home/airflow/.local/lib/python3.10/site-packages/airflow/models/taskinstance.py", line 3173, in _execute_task
    return _execute_task(self, context, task_orig)
  File "/home/airflow/.local/lib/python3.10/site-packages/airflow/models/taskinstance.py", line 767, in _execute_task
    result = _execute_callable(context=context, **execute_callable_kwargs)
  File "/home/airflow/.local/lib/python3.10/site-packages/airflow/models/taskinstance.py", line 733, in _execute_callable
    return ExecutionCallableRunner(
  File "/home/airflow/.local/lib/python3.10/site-packages/airflow/utils/operator_helpers.py", line 252, in run
    return self.func(*args, **kwargs)
  File "/home/airflow/.local/lib/python3.10/site-packages/airflow/models/baseoperator.py", line 406, in wrapper
    return func(self, *args, **kwargs)
  File "/home/airflow/.local/lib/python3.10/site-packages/airflow/operators/python.py", line 238, in execute
    return_value = self.execute_callable()
  File "/home/airflow/.local/lib/python3.10/site-packages/airflow/operators/python.py", line 256, in execute_callable
    return runner.run(*self.op_args, **self.op_kwargs)
  File "/home/airflow/.local/lib/python3.10/site-packages/airflow/utils/operator_helpers.py", line 252, in run
    return self.func(*args, **kwargs)
  File "/opt/airflow/dags/read_csv_sum_dag.py", line 10, in read_and_sum
    total = df['value'].sum()  # Replace 'value' with your actual column name
  File "/home/airflow/.local/lib/python3.10/site-packages/pandas/core/frame.py", line 3893, in __getitem__
    indexer = self.columns.get_loc(key)
  File "/home/airflow/.local/lib/python3.10/site-packages/pandas/core/indexes/base.py", line 3798, in get_loc
    raise KeyError(key) from err
KeyError: 'value'
[2025-05-30T05:23:57.651+0000] {local_task_job_runner.py:261} INFO - Task exited with return code 1
[2025-05-30T05:23:57.668+0000] {taskinstance.py:3891} INFO - 0 downstream tasks scheduled from follow-on schedule check
[2025-05-30T05:23:57.670+0000] {local_task_job_runner.py:240} INFO - ::endgroup::
