[2025-05-28T04:51:48.688+0000] {local_task_job_runner.py:123} INFO - ::group::Pre task execution logs
[2025-05-28T04:51:48.724+0000] {taskinstance.py:2603} INFO - Dependencies all met for dep_context=non-requeueable deps ti=<TaskInstance: global_street_food_analysis_dag.run_street_food_analysis manual__2025-05-28T04:51:47.111247+00:00 [queued]>
[2025-05-28T04:51:48.750+0000] {taskinstance.py:2603} INFO - Dependencies all met for dep_context=requeueable deps ti=<TaskInstance: global_street_food_analysis_dag.run_street_food_analysis manual__2025-05-28T04:51:47.111247+00:00 [queued]>
[2025-05-28T04:51:48.750+0000] {taskinstance.py:2856} INFO - Starting attempt 1 of 2
[2025-05-28T04:51:48.788+0000] {taskinstance.py:2879} INFO - Executing <Task(BashOperator): run_street_food_analysis> on 2025-05-28 04:51:47.111247+00:00
[2025-05-28T04:51:48.794+0000] {standard_task_runner.py:72} INFO - Started process 181 to run task
[2025-05-28T04:51:48.807+0000] {standard_task_runner.py:104} INFO - Running: ['airflow', 'tasks', 'run', 'global_street_food_analysis_dag', 'run_street_food_analysis', 'manual__2025-05-28T04:51:47.111247+00:00', '--job-id', '4', '--raw', '--subdir', 'DAGS_FOLDER/global_food.py', '--cfg-path', '/tmp/tmpz0zv81n4']
[2025-05-28T04:51:48.809+0000] {standard_task_runner.py:105} INFO - Job 4: Subtask run_street_food_analysis
[2025-05-28T04:51:48.911+0000] {task_command.py:467} INFO - Running <TaskInstance: global_street_food_analysis_dag.run_street_food_analysis manual__2025-05-28T04:51:47.111247+00:00 [running]> on host 96c1916b9317
[2025-05-28T04:51:49.041+0000] {taskinstance.py:3122} INFO - Exporting env vars: AIRFLOW_CTX_DAG_OWNER='airflow' AIRFLOW_CTX_DAG_ID='global_street_food_analysis_dag' AIRFLOW_CTX_TASK_ID='run_street_food_analysis' AIRFLOW_CTX_EXECUTION_DATE='2025-05-28T04:51:47.111247+00:00' AIRFLOW_CTX_TRY_NUMBER='1' AIRFLOW_CTX_DAG_RUN_ID='manual__2025-05-28T04:51:47.111247+00:00'
[2025-05-28T04:51:49.043+0000] {taskinstance.py:731} INFO - ::endgroup::
[2025-05-28T04:51:49.091+0000] {subprocess.py:63} INFO - Tmp dir root location: /tmp
[2025-05-28T04:51:49.094+0000] {subprocess.py:75} INFO - Running command: ['/usr/bin/bash', '-c', 'spark-submit /home/sreelakshmi/pyspark_airflow/scripts/food.py']
[2025-05-28T04:51:49.135+0000] {subprocess.py:86} INFO - Output:
[2025-05-28T04:51:49.195+0000] {subprocess.py:93} INFO - /opt/spark/bin/load-spark-env.sh: line 68: ps: command not found
[2025-05-28T04:51:54.485+0000] {subprocess.py:93} INFO - python3: can't open file '/home/sreelakshmi/pyspark_airflow/scripts/food.py': [Errno 2] No such file or directory
[2025-05-28T04:51:54.520+0000] {subprocess.py:93} INFO - 25/05/28 04:51:54 INFO ShutdownHookManager: Shutdown hook called
[2025-05-28T04:51:54.529+0000] {subprocess.py:93} INFO - 25/05/28 04:51:54 INFO ShutdownHookManager: Deleting directory /tmp/spark-4c1eee75-c1fa-4ae2-a1ec-a6c7f767c30f
[2025-05-28T04:51:54.586+0000] {subprocess.py:97} INFO - Command exited with return code 2
[2025-05-28T04:51:54.607+0000] {taskinstance.py:3301} ERROR - Task failed with exception
Traceback (most recent call last):
  File "/home/airflow/.local/lib/python3.10/site-packages/airflow/models/taskinstance.py", line 767, in _execute_task
    result = _execute_callable(context=context, **execute_callable_kwargs)
  File "/home/airflow/.local/lib/python3.10/site-packages/airflow/models/taskinstance.py", line 733, in _execute_callable
    return ExecutionCallableRunner(
  File "/home/airflow/.local/lib/python3.10/site-packages/airflow/utils/operator_helpers.py", line 252, in run
    return self.func(*args, **kwargs)
  File "/home/airflow/.local/lib/python3.10/site-packages/airflow/models/baseoperator.py", line 406, in wrapper
    return func(self, *args, **kwargs)
  File "/home/airflow/.local/lib/python3.10/site-packages/airflow/operators/bash.py", line 249, in execute
    raise AirflowException(
airflow.exceptions.AirflowException: Bash command failed. The command returned a non-zero exit code 2.
[2025-05-28T04:51:54.649+0000] {taskinstance.py:1225} INFO - Marking task as UP_FOR_RETRY. dag_id=global_street_food_analysis_dag, task_id=run_street_food_analysis, run_id=manual__2025-05-28T04:51:47.111247+00:00, execution_date=20250528T045147, start_date=20250528T045148, end_date=20250528T045154
[2025-05-28T04:51:54.703+0000] {taskinstance.py:340} INFO - ::group::Post task execution logs
[2025-05-28T04:51:54.705+0000] {standard_task_runner.py:124} ERROR - Failed to execute job 4 for task run_street_food_analysis (Bash command failed. The command returned a non-zero exit code 2.; 181)
Traceback (most recent call last):
  File "/home/airflow/.local/lib/python3.10/site-packages/airflow/task/task_runner/standard_task_runner.py", line 117, in _start_by_fork
    ret = args.func(args, dag=self.dag)
  File "/home/airflow/.local/lib/python3.10/site-packages/airflow/cli/cli_config.py", line 49, in command
    return func(*args, **kwargs)
  File "/home/airflow/.local/lib/python3.10/site-packages/airflow/utils/cli.py", line 115, in wrapper
    return f(*args, **kwargs)
  File "/home/airflow/.local/lib/python3.10/site-packages/airflow/cli/commands/task_command.py", line 483, in task_run
    task_return_code = _run_task_by_selected_method(args, _dag, ti)
  File "/home/airflow/.local/lib/python3.10/site-packages/airflow/cli/commands/task_command.py", line 256, in _run_task_by_selected_method
    return _run_raw_task(args, ti)
  File "/home/airflow/.local/lib/python3.10/site-packages/airflow/cli/commands/task_command.py", line 341, in _run_raw_task
    return ti._run_raw_task(
  File "/home/airflow/.local/lib/python3.10/site-packages/airflow/utils/session.py", line 97, in wrapper
    return func(*args, session=session, **kwargs)
  File "/home/airflow/.local/lib/python3.10/site-packages/airflow/models/taskinstance.py", line 2995, in _run_raw_task
    return _run_raw_task(
  File "/home/airflow/.local/lib/python3.10/site-packages/airflow/models/taskinstance.py", line 273, in _run_raw_task
    TaskInstance._execute_task_with_callbacks(
  File "/home/airflow/.local/lib/python3.10/site-packages/airflow/models/taskinstance.py", line 3149, in _execute_task_with_callbacks
    result = self._execute_task(context, task_orig)
  File "/home/airflow/.local/lib/python3.10/site-packages/airflow/models/taskinstance.py", line 3173, in _execute_task
    return _execute_task(self, context, task_orig)
  File "/home/airflow/.local/lib/python3.10/site-packages/airflow/models/taskinstance.py", line 767, in _execute_task
    result = _execute_callable(context=context, **execute_callable_kwargs)
  File "/home/airflow/.local/lib/python3.10/site-packages/airflow/models/taskinstance.py", line 733, in _execute_callable
    return ExecutionCallableRunner(
  File "/home/airflow/.local/lib/python3.10/site-packages/airflow/utils/operator_helpers.py", line 252, in run
    return self.func(*args, **kwargs)
  File "/home/airflow/.local/lib/python3.10/site-packages/airflow/models/baseoperator.py", line 406, in wrapper
    return func(self, *args, **kwargs)
  File "/home/airflow/.local/lib/python3.10/site-packages/airflow/operators/bash.py", line 249, in execute
    raise AirflowException(
airflow.exceptions.AirflowException: Bash command failed. The command returned a non-zero exit code 2.
[2025-05-28T04:51:54.767+0000] {local_task_job_runner.py:261} INFO - Task exited with return code 1
[2025-05-28T04:51:54.793+0000] {taskinstance.py:3891} INFO - 0 downstream tasks scheduled from follow-on schedule check
[2025-05-28T04:51:54.795+0000] {local_task_job_runner.py:240} INFO - ::endgroup::
